Workbook

Sheet Read Me
A1: Evidence Register: Brownfield to Repo 2.0 (logistics shipment, fleet, routing ops)
A2: Delta-Team, AI-FDE Sprint 3. As of 2026-10-08. Built from the repository by deliverables/_build/build_workbook.py.
A4: How to use this workbook
A5: Start on Dashboard for the headline numbers. Every other sheet is the detail behind one tile.
A6: Each evidence row links to the file on GitHub (private repository; sign in to open). SHA-256 lets anyone check the file is unchanged.
A7: Filters are on every table. Green = done, amber = partial or changed, red = not met, blocked or deferred.
A9: Sheets
A10: Dashboard: headline numbers, all computed by formula from the sheets below.
A11: Repo 1.0 vs 2.0: capability by capability, what was delivered and what exists now, with findings and evidence.
A12: File Inventory: files and code lines per area, delivered commit 698e858 vs current main.
A13: Evidence Register: all 146 hash-registered evidence files, with stage, findings addressed, rubric criteria and link.
A14: Findings: the 62 baseline findings with severity, final disposition and rubric criteria.
... A28: No real AI model was called; all AI evidence uses the deterministic provider. Nothing is deployed. No business KPI moved; K1 to K8 are computed from a static synthetic fixture. One operator plus one agent built, tested and graded the work: no independent review.

Sheet Dashboard
A1: Dashboard: Repo 1.0 → Repo 2.0, in numbers
A2: Every value below is a formula over the detail sheets. As of 2026-10-08.
A4: Evidence
A5: Hash-registered evidence files | B5: =COUNTA('Evidence Register'!A4:A149) -> 146
A6: Files touching R1 | B6: =COUNTIF('Evidence Register'!I4:I149,"*R1*") -> 30
A7: Files touching R2 | B7: =COUNTIF('Evidence Register'!I4:I149,"*R2*") -> 73
A8: Files touching R3 | B8: =COUNTIF('Evidence Register'!I4:I149,"*R3*") -> 20
A9: Files touching R4 | B9: =COUNTIF('Evidence Register'!I4:I149,"*R4*") -> 20
A10: Files touching R5 | B10: =COUNTIF('Evidence Register'!I4:I149,"*R5*") -> 39
A12: Findings
A13: Baseline findings | B13: =COUNTA(Findings!A4:A65) -> 62
A14: Severity S1 | B14: =COUNTIF(Findings!B4:B65,"S1") -> 25
A15: FIXED | B15: =COUNTIF(Findings!D4:D65,"FIXED") -> 43
A16: FIXED-IN-TREE | B16: =COUNTIF(Findings!D4:D65,"FIXED-IN-TREE") -> 4
A17: PARTIAL | B17: =COUNTIF(Findings!D4:D65,"PARTIAL") -> 10
A18: CHANGED | B18: =COUNTIF(Findings!D4:D65,"CHANGED") -> 2
A19: DEFERRED | B19: =COUNTIF(Findings!D4:D65,"DEFERRED") -> 2
A20: ACCEPTED-PROPOSED | B20: =COUNTIF(Findings!D4:D65,"ACCEPTED-PROPOSED") -> 1
A22: Proof
A23: Attacks that succeed on Repo 1.0 (of 12) | B23: =COUNTIF('Red Team'!E4:E15,"Succeeded") -> 10
A24: Attacks that succeed on Repo 2.0 (of 12) | B24: =COUNTIF('Red Team'!G4:G15,"Succeeded") -> 0
A25: Readiness gates passed (of 12) | B25: =COUNTIF('Go-No-Go'!D4:D15,"PASS*") -> 6
A26: Readiness gates failed | B26: =COUNTIF('Go-No-Go'!D4:D15,"FAIL*") -> 5
A27: Tracked files in the application folder, 1.0 → 2.0 | B27: =TEXT('File Inventory'!B18,"0")&" → "&TEXT('File Inventory'!C18,"0") -> 51 → 158
A29: Governance
A30: Open questions decided or ratified | B30: =COUNTIF(Decisions!C4:C26,"DECIDED")+COUNTIF(Decisions!C4:C26,"RATIFIED") -> 22
A31: Open questions deferred | B31: =COUNTIF(Decisions!C4:C26,"DEFERRED") -> 1
A32: Rubric sub-dimensions | B32: ='Rubric Coverage'!H9 -> 36
A33: Sub-dimensions MET | B33: ='Rubric Coverage'!D9 -> 24
A34: Sub-dimensions NOT MET or BLOCKED | B34: ='Rubric Coverage'!F9+'Rubric Coverage'!G9 -> 3
A35: Risk acceptances signed by a named person | B35: 0 | C35: Input: 0 of 12 (docs/25-governance/risk-acceptance-register.md)

Sheet Repo 1.0 vs 2.0
A1: Repo 1.0 (as delivered) vs Repo 2.0 (as built)
A2: Repo 1.0 = commit 698e858 (delivered bytes). Repo 2.0 = main today. Status is the agent's reading of the finding dispositions; see Findings.
A3: Area | B3: Repo 1.0 (as delivered) | C3: Repo 2.0 (as built) | D3: Status | E3: Findings | F3: Evidence
A4: Version control and quick-start | B4: Not under version control; documented test command fails (exit 2, missing httpx); run command wrong | C4: Git with baseline tags; quick-start works; 181 passed, 1 skipped, 7 expected xfail | D4: Fixed | E4: F-01, F-02, F-03 | F4: evidence/07-repo-assessment/EVD-C-02-quickstart-transcript.txt; evidence/15-modernization/EVD-H-02-quickstart-after.txt
A5: Tests and coverage | B5: 3 tests (0 collected without httpx); coverage 45% | C5: 181 tests plus 7 characterisation tests that pin old behaviour; 97% coverage (apps and etl) | D5: Fixed | E5: F-51 | F5: evidence/34-after-kpis/EVD-O-01-after-kpis.json
A6: Dependencies and supply chain | B6: Versions pinned but no lockfile or hashes; no SBOM | C6: Hash-pinned lockfiles; SBOM (runtime 21, dev 58 components); 0 known vulnerabilities | D6: Fixed | E6: F-04, F-49 | F6: evidence/27-hardening/EVD-M-01-pip-audit-runtime.json
A7: Identity | B7: Role read from a client-supplied X-User-Role header | C7: Signed bearer token (HS256, alg none rejected); JWKS verifier is a fail-closed stub; no identity provider | D7: Fixed (interim scheme) | E7: F-17 | F7: evidence/26-tevv/EVD-L-03-redteam-v2.json (RT-02, RT-11)
A8: Authorisation | B8: Flat five-role allow-list including a persona from another domain; Rego file used by no code | C8: Deny-by-default policy engine driven by access-semantics.yaml (persona x entity x purpose, field mask or drop); Rego generated from it and tested in CI; scope narrowing declared but not enforced | D8: Fixed (scope partial) | E8: F-18, F-19, F-21 | F8: evidence/26-tevv/EVD-L-03-redteam-v2.json (RT-03)
A9: Record lookup | B9: Scans every column; a miss returns the wrong record; REC-0001 key collides across entities | C9: Identifier must match the entity key pattern (422); a miss is 404 and audited; colliding rows quarantined | D9: Fixed | E9: F-30, F-31, F-32 | F9: evidence/26-tevv/EVD-L-03-redteam-v2.json (RT-04 to RT-06)
A10: AI endpoint | B10: No authorisation; guardrail_status not_enforced; no output schema; str.format on untrusted text; output echoes the first column | C10: Authorised and rate-limited; allow-listed, sanitised context; schema and leak checks; fallback then abstain; suggest-only. Deterministic provider only | D10: Fixed (no real model) | E10: F-20, F-22, F-23, F-24, F-25, F-29 | F10: evidence/26-tevv/EVD-L-02-final-eval-run.json; EVD-L-03 RT-01, RT-07 to RT-09, RT-12
A11: Human approval | B11: None | C11: Every suggestion registered; approve or reject once (409 on repeat); requester may approve their own (RA-04) | D11: Fixed (no four-eyes) | E11: F-26 | F11: evidence/26-tevv/EVD-L-03-redteam-v2.json (RT-10)
A12: Model provenance and tokens | B12: Model id is a constant; token count fabricated | C12: Model, version, prompt version and config hash on every answer; token count labelled as an estimate | D12: Partial | E12: F-27, F-28 | F12: docs/final-prd/final-ai-agent-baseline.md
A13: Audit | B13: Records time, action, details only; naive timestamps; local file | C13: Hash-chained events with actor, correlation id, tenant, resource and policy decision; verify endpoint; tampering detected; still a local file sink | D13: Partial | E13: F-43, F-44, F-45 | F13: evidence/31-observability/EVD-N-02-reconstruction.json
A14: Data quality | B14: Duplicates, blank rows, impossible timestamps, polluted categories; ETL counts defects and discards them | C14: ETL validates with the API's rules; bad rows quarantined with a run id; curated layer; raw fixture left byte-identical | D14: Fixed | E14: F-33 to F-41, F-58, F-61, F-62 | F14: evidence/11-data-context/EVD-D-02-enum-violations.csv
... A23: Encryption | B23: No TLS, at-rest or key management statement | C23: Unchanged; deferred until a platform exists | D23: Deferred | E23: F-16 | F23: docs/42-executive/residual-risks.md

Sheet File Inventory
A1: Files and code lines per area: Repo 1.0 vs Repo 2.0
A2: Tracked files under 07-logistics-shipment-fleet-routing-ops/. Code lines = .py .ts .rego .js .tf .sh. Counted with git at build time.
A3: Area | B3: Files 1.0 | C3: Files 2.0 | D3: Files change | E3: Code lines 1.0 | F3: Code lines 2.0 | G3: Lines change
A4: apps/api | B4: 6 | C4: 29 | D4: =C4-B4 -> 23 | E4: 73 | F4: 2118 | G4: =F4-E4 -> 2045
A5: tests | B5: 3 | C5: 27 | D5: =C5-B5 -> 24 | E5: 30 | F5: 2198 | G5: =F5-E5 -> 2168
A6: other (root files) | B6: 10 | C6: 24 | D6: =C6-B6 -> 14 | E6: 0 | F6: 6 | G6: =F6-E6 -> 6
A7: scripts | B7: 1 | C7: 20 | D7: =C7-B7 -> 19 | E7: 33 | F7: 3541 | G7: =F7-E7 -> 3508
A8: data | B8: 11 | C8: 14 | D8: =C8-B8 -> 3 | E8: 0 | F8: 0 | G8: =F8-E8 -> 0
A9: evaluation | B9: 0 | C9: 11 | D9: =C9-B9 -> 11 | E9: 0 | F9: 624 | G9: =F9-E9 -> 624
A10: docs | B10: 9 | C10: 9 | D10: =C10-B10 -> 0 | E10: 0 | F10: 0 | G10: =F10-E10 -> 0
A11: apps/web | B11: 3 | C11: 8 | D11: =C11-B11 -> 5 | E11: 10 | F11: 100 | G11: =F11-E11 -> 90
A12: observability | B12: 1 | C12: 5 | D12: =C12-B12 -> 4 | E12: 0 | F12: 0 | G12: =F12-E12 -> 0
A13: .github | B13: 1 | C13: 3 | D13: =C13-B13 -> 2 | E13: 0 | F13: 0 | G13: =F13-E13 -> 0
A14: etl | B14: 2 | C14: 3 | D14: =C14-B14 -> 1 | E14: 20 | F14: 337 | G14: =F14-E14 -> 317
A15: policy | B15: 1 | C15: 2 | D15: =C15-B15 -> 1 | E15: 12 | F15: 323 | G15: =F15-E15 -> 311
... A17: infra | B17: 1 | C17: 1 | D17: =C17-B17 -> 0 | E17: 5 | F17: 16 | G17: =F17-E17 -> 11
A18: Total | B18: =SUM(B4:B17) -> 51 | C18: =SUM(C4:C17) -> 158 | D18: =SUM(D4:D17) -> 107 | E18: =SUM(E4:E17) -> 197 | F18: =SUM(F4:F17) -> 9281 | G18: =SUM(G4:G17) -> 9084

Sheet Evidence Register
A1: Evidence register: 146 hash-registered files
A2: Source: evidence/EVIDENCE-INDEX.csv (derived from the per-folder MANIFEST.md files). Verified: every SHA-256 matches the file (EVD-R-03 verifier).
A3: Evidence ID | B3: Stage | C3: Stage name | D3: Phase | E3: Folder | F3: Type | G3: Produced (UTC) | H3: Findings addressed | I3: Rubric criteria | J3: Cited by | K3: SHA-256 | L3: Link
A4: EVD-A-01-baseline-file-manifest | B4: A | C4: Engagement mobilisation and read-only orientation | D4: 1 Understand | E4: 00-preflight | F4: sha256 | G4: 2026-10-08T08:42:57Z | H4: F-01 | I4: R1 | J4: docs/00-preflight/operating-contract/decision-log.md | K4: 8eb89d1ff2dd835d78f823662e6dca0713b94034f71263504653d0cabba3fac2 | L4: open
A5: EVD-A-01-delivered-vs-committed | B5: A | C5: Engagement mobilisation and read-only orientation | D5: 1 Understand | E5: 00-preflight | F5: csv | G5: 2026-10-08T08:42:57Z | H5: F-01 | I5: R1 | J5: docs/00-preflight/operating-contract/decision-log.md | K5: dd2382a160a0c7586ca6ed393b90ec26b4113f6bb28e106fa2c1bcdeeb6ca30c | L5: open
A6: EVD-A-01-tag-verification | B6: A | C6: Engagement mobilisation and read-only orientation | D6: 1 Understand | E6: 00-preflight | F6: txt | G6: 2026-10-08T08:42:57Z | H6: F-01 | I6: R1 | J6: docs/00-preflight/operating-contract/decision-log.md | K6: a507d3d45cee3dd0598ca179c229ae213ef15c999ada6eb1353c4eea4be4b70b | L6: open
A7: EVD-A-02-spine-tree | B7: A | C7: Engagement mobilisation and read-only orientation | D7: 1 Understand | E7: 00-preflight | F7: txt | G7: 2026-10-08T08:42:57Z | I7: R1 | J7: docs/00-preflight/operating-contract/decision-log.md | K7: 38db5b75d91b98521a40d52a5b623280bb9d038890ab23574a0ece327e2b0406 | L7: open
A8: EVD-A-03-toolchain-snapshot | B8: A | C8: Engagement mobilisation and read-only orientation | D8: 1 Understand | E8: 00-preflight | F8: txt | G8: 2026-10-08T09:00:00Z | I8: R1 | J8: docs/00-preflight/discovery/environment-snapshot.md | K8: b9bc4bf6585621edcdd934895f923a0e2d4a643e0c5fed30c418715993b3231f | L8: open
A9: EVD-A-03c-runtime-upgrade-compat | B9: A | C9: Engagement mobilisation and read-only orientation | D9: 1 Understand | E9: 00-preflight | F9: txt | G9: 2026-10-08T09:10:00Z | I9: R1 | J9: docs/00-preflight/discovery/environment-snapshot.md | K9: 4c48b3c48ba51da41bc0c7ef2a42b75002ab8738bffa9cedda85b2271aa6901a | L9: open
A10: EVD-A-03b-windows-host-snapshot | B10: A | C10: Engagement mobilisation and read-only orientation | D10: 1 Understand | E10: 00-preflight | F10: txt | G10: 2026-10-08T09:10:00Z | I10: R1 | J10: docs/00-preflight/discovery/environment-snapshot.md | K10: 7e61ec7eb27d9126ac1ab9fa137a8eb0c009e5609ab3c56b8ab9d1340a82f345 | L10: open
A11: EVD-A-03d-windows-host-snapshot-2 | B11: A | C11: Engagement mobilisation and read-only orientation | D11: 1 Understand | E11: 00-preflight | F11: txt | G11: 2026-10-08T09:15:00Z | I11: R1 | J11: docs/00-preflight/discovery/environment-snapshot.md | K11: 7569293ca130291d004dbb8cbfef68dd2dcb83cfcdad29c85b1197ad5ca135f6 | L11: open
A12: EVD-A-03e-operator-statement | B12: A | C12: Engagement mobilisation and read-only orientation | D12: 1 Understand | E12: 00-preflight | F12: txt | G12: 2026-10-08T09:20:00Z | I12: R1 | J12: docs/00-preflight/discovery/environment-snapshot.md | K12: 328cdba5fb736a07f1af70c99fd01588b56e8b0ca4d5d8500c859f5c90ae0d18 | L12: open
A13: EVD-A-04-repo-tree-annotated | B13: A | C13: Engagement mobilisation and read-only orientation | D13: 1 Understand | E13: 00-preflight | F13: txt | G13: 2026-10-08T09:40:00Z | I13: R1 | J13: docs/00-preflight/discovery/ | K13: 6dd1c997087a9a453650d2228a2a9a01aa075d9ba810905e3e0f83705c457347 | L13: open
A14: EVD-A-04b-data-profile | B14: A | C14: Engagement mobilisation and read-only orientation | D14: 1 Understand | E14: 00-preflight | F14: txt | G14: 2026-10-08T09:40:00Z | I14: R1 | J14: docs/00-preflight/discovery/ | K14: b81c7055f0bad40deeb41ff0b76a0cb6b037420a5a4a575e5152d7c12e14d37e | L14: open
A15: EVD-A-05-confirmation-items | B15: A | C15: Engagement mobilisation and read-only orientation | D15: 1 Understand | E15: 00-preflight | F15: txt | G15: 2026-10-08T10:10:00Z | I15: R1 | J15: docs/00-preflight/operating-contract/operating-contract-readiness.md | K15: 8c5b0b96519512cf2c80b94b9b92f167671669fcb6629cb32f8fe3ac6f6ec16c | L15: open
A16: EVD-A-06-ai-economics-profile | B16: A | C16: Engagement mobilisation and read-only orientation | D16: 1 Understand | E16: 00-preflight | F16: json | G16: 2026-10-08T10:30:00Z | I16: R1 | J16: docs/00-preflight/ai-economics/ | K16: d38d6c61ea774cf11348a9a7c5a497c5eb77c04e78dfed773252fe9ca8d664d5 | L16: open
A17: EVD-A-07-stage-a-exit-checks | B17: A | C17: Engagement mobilisation and read-only orientation | D17: 1 Understand | E17: 00-preflight | F17: txt | G17: 2026-10-08T09:42:06Z | I17: R1 | J17: docs/00-preflight/stage-a-gate.md | K17: f71de9f9325e9e14cd2def90df779de5e577db84683bf803e9720bf246fbf194 | L17: open
A18: EVD-A-04c-correlation-recount | B18: A | C18: Engagement mobilisation and read-only orientation | D18: 1 Understand | E18: 00-preflight | F18: txt | G18: 2026-10-08T10:18:49Z | I18: R1 | J18: decision-log D-012 | K18: c2600111796cca839e726d805f30ac37f26904872fdff92ceaebd1663716707c | L18: open
... A22: EVD-C-04-flow-to-code-trace | B22: C | C22: Baseline: KPIs, current state, root cause, behaviour | D22: 1 Understand | E22: 05-current-state | F22: md | G22: 2026-10-08T09:47:28Z | I22: R1 | J22: docs/05-current-state/business-workflow-map.md | K22: 4ddd2316209f21774efc175f323585b52c0363bda79b040be3515c3fbd7559f1 | L22: open
A23: EVD-C-02-quickstart-transcript | B23: C | C23: Baseline: KPIs, current state, root cause, behaviour | D23: 1 Understand | E23: 07-repo-assessment | F23: txt | G23: 2026-10-08T09:45:54Z | H23: F-02 | I23: R1 | J23: docs/07-repo-assessment/baseline-behaviour.md | K23: 74e85bd8cec2ade87fc4ccf8a95b40552928010bfd689e761b21868fdf541581 | L23: open
A24: EVD-C-03-transcript | B24: C | C24: Baseline: KPIs, current state, root cause, behaviour | D24: 1 Understand | E24: 07-repo-assessment | F24: txt | G24: 2026-10-08T09:45:54Z | I24: R1 | J24: docs/07-repo-assessment/baseline-behaviour.md | K24: e00e2c43b291f1a06e7144f029873e2b4422672353800328fc2534d30060b743 | L24: open
A25: EVD-C-03-junit | B25: C | C25: Baseline: KPIs, current state, root cause, behaviour | D25: 1 Understand | E25: 07-repo-assessment | F25: xml | G25: 2026-10-08T09:45:54Z | I25: R1 | J25: docs/07-repo-assessment/baseline-behaviour.md | K25: 1d96dc44eb81588a1155ba4566d8d87ab7ef22d62ba21b803f7835d3926ca8da | L25: open
A26: EVD-C-03-coverage | B26: C | C26: Baseline: KPIs, current state, root cause, behaviour | D26: 1 Understand | E26: 07-repo-assessment | F26: xml | G26: 2026-10-08T09:45:54Z | I26: R1 | J26: docs/07-repo-assessment/baseline-behaviour.md | K26: 85210479df1b835c07459cca3a26494695ede817d7399bc85133811e92b607e8 | L26: open
A27: EVD-C-07-findings-index | B27: C | C27: Baseline: KPIs, current state, root cause, behaviour | D27: 1 Understand | E27: 07-repo-assessment | F27: json | G27: 2026-10-08T09:47:28Z | I27: R1 | J27: docs/07-repo-assessment/technical-debt-register.md | K27: 6c387bfd6ea34ba4aca6464d7bcea97e164f439d89acc063516ecec85e016a98 | L27: open
A28: EVD-C-08-characterization-junit | B28: C | C28: Baseline: KPIs, current state, root cause, behaviour | D28: 1 Understand | E28: 07-repo-assessment | F28: xml | G28: 2026-10-08T09:48:24Z | H28: F-19;F-20;F-24;F-32;F-51 | I28: R1 | J28: docs/07-repo-assessment/stage-c-gate.md | K28: b35040581e79ee0e1b912f8399b855e60ef591ad76c24faa27eb7c0169ffd90e | L28: open
A29: EVD-C-09-stage-c-exit-checks | B29: C | C29: Baseline: KPIs, current state, root cause, behaviour | D29: 1 Understand | E29: 07-repo-assessment | F29: txt | G29: 2026-10-08T09:48:24Z | I29: R1 | J29: docs/07-repo-assessment/stage-c-gate.md | K29: 61b3292ae9002e9da7fbdc5d30c3074b8c983a2ac01c20c0fd1fdfadd44b9828 | L29: open
A30: EVD-E-04-stage-e-checks | B30: E | C30: Intervention qualification and initial PRD | D30: 2 Define | E30: 08-ai-qualification | F30: txt | G30: 2026-10-08T09:55:03Z | I30: R4 | J30: docs/09-initial-prd/stage-e-gate.md | K30: 56b7058b10ff961bc3091af9007b241a45b7f3ccc649790a6345f1f640e069c6 | L30: open
A31: EVD-E-03-requirement-trace | B31: E | C31: Intervention qualification and initial PRD | D31: 2 Define | E31: 09-initial-prd | F31: csv | G31: 2026-10-08T09:55:03Z | I31: R4 | J31: docs/09-initial-prd/initial-prd-traceability.md | K31: 079f95fb2f36f6dc60697bafebf6720ebb4696699722d19f7335786cb4a00453 | L31: open
A32: EVD-F-01-adr-index | B32: F | C32: Target architecture, data and context, specs, traceability | D32: 2 Define | E32: 10-architecture | F32: txt | G32: 2026-10-08T10:03:32Z | H32: F-53 | I32: R4 | J32: stage-f-gate.md (F-X1) | K32: 4cae717c359d65180ef203aeda719971c6f37e405a160e033495cc8bcf5d450d | L32: open
A33: EVD-D-01-field-coverage | B33: D | C33: Semantic layer extraction | D33: 2 Define | E33: 11-data-context | F33: csv | G33: 2026-10-08T09:53:26Z | H33: F-37 | I33: R2 | J33: docs/11-data-context/stage-d-gate.md | K33: 298054a6d5c07cc41202e4816df2e3f90438d03b9e8044747e3c06828fce293c | L33: open
A34: EVD-D-02-enum-violations | B34: D | C34: Semantic layer extraction | D34: 2 Define | E34: 11-data-context | F34: csv | G34: 2026-10-08T09:53:26Z | I34: R2 | J34: docs/11-data-context/stage-d-gate.md | K34: 358e7392b8fad0b672ac5a4ee4b0e352b863e544f23a1ba9a637aac1c51f2ea7 | L34: open
A35: EVD-D-03-rule-to-gap-trace | B35: D | C35: Semantic layer extraction | D35: 2 Define | E35: 11-data-context | F35: csv | G35: 2026-10-08T09:53:26Z | I35: R2 | J35: docs/11-data-context/stage-d-gate.md | K35: 5388fb6ad5f0454598a0488454a4012d3de54936d2defb84bbce6134f3c5a582 | L35: open
A36: EVD-D-04-access-semantics-matrix | B36: D | C36: Semantic layer extraction | D36: 2 Define | E36: 11-data-context | F36: csv | G36: 2026-10-08T09:53:26Z | I36: R2 | J36: docs/11-data-context/stage-d-gate.md | K36: f95609856b8284299d323c48befa7e688f60c55d31c5ef508581d05121b005c8 | L36: open
A37: EVD-D-05-rule-baseline | B37: D | C37: Semantic layer extraction | D37: 2 Define | E37: 11-data-context | F37: json | G37: 2026-10-08T09:53:26Z | I37: R2 | J37: docs/11-data-context/stage-d-gate.md | K37: d44af9df668fa79e00af0ee2da9c0cdad84ff6e6bf9ac1c8b225d9d085132d55 | L37: open
A38: EVD-D-05-semantic-layer-junit | B38: D | C38: Semantic layer extraction | D38: 2 Define | E38: 11-data-context | F38: xml | G38: 2026-10-08T09:53:26Z | I38: R2 | J38: docs/11-data-context/stage-d-gate.md | K38: cb1fc7cbbef53af7b1e21ab6a657e65dcc0b84dcfe178ca91dad5ebb127dae45 | L38: open
A39: EVD-D-05-generated-semantic-layer | B39: D | C39: Semantic layer extraction | D39: 2 Define | E39: 11-data-context | F39: json | G39: 2026-10-08T09:53:26Z | I39: R2 | J39: docs/11-data-context/stage-d-gate.md | K39: edf62772dc55687db93dd20f3e520331db0e5f247d936c0ced401cee79083bf2 | L39: open
A40: EVD-D-06-semantic-v2-junit | B40: D | C40: Semantic layer extraction | D40: 2 Define | E40: 11-data-context | F40: xml | G40: 2026-10-08T16:53:46Z | I40: R2 | J40: docs/11-data-context/semantic-layer-v2-alignment.md | K40: fc7501deca0483cf68eb7977ae3c6595f49e187be7338b691fcd27e051c55fd7 | L40: open
A41: EVD-D-06-semantic-layer-v2-hashes | B41: D | C41: Semantic layer extraction | D41: 2 Define | E41: 11-data-context | F41: json | G41: 2026-10-08T16:53:46Z | I41: R2 | J41: docs/11-data-context/semantic-layer-v2-alignment.md | K41: cffd158ffa517b9874ceb7b1e4ee15fc535273b9d437ad04a95bede40eb19fdf | L41: open
A42: EVD-F-03-openapi | B42: F | C42: Target architecture, data and context, specs, traceability | D42: 2 Define | E42: 12-specs | F42: yaml | G42: 2026-10-08T10:02:44Z | H42: F-25;F-43;F-50 | I42: R4 | J42: docs/12-specs/spec-readiness.md; stage-f-gate.md | K42: 6016a47d34dccadb44c6f7237cd3077f44edce88f5029801d5d1249272215c87 | L42: open
A43: EVD-F-03-openapi-validation | B43: F | C43: Target architecture, data and context, specs, traceability | D43: 2 Define | E43: 12-specs | F43: txt | G43: 2026-10-08T10:02:44Z | H43: F-25;F-43;F-50 | I43: R4 | J43: docs/12-specs/spec-readiness.md; stage-f-gate.md | K43: 0633960f82600f6fbf80d68cd7b6e60e9f2d87242ec53df855af06b55a35cd1a | L43: open
...

Sheet Findings
A1: 62 baseline findings and their final disposition
A2: Source: evidence/13-traceability/EVD-F-04b-finding-disposition-final.csv; rubric criteria from EVD-S-02. S1 = most severe.
A3: Finding | B3: Severity | C3: Title | D3: Final disposition | E3: Rubric criteria | F3: Evidence | G3: Owner role | H3: Note
A4: F-01 | B4: S1 | C4: The repository is not under version control | D4: FIXED | E4: R1;R3 | F4: evidence/00-preflight/EVD-A-01-tag-verification.txt | G4: n/a
A5: F-02 | B5: S2 | C5: The documented test command cannot run | D5: FIXED | E5: R1;R4 | F5: evidence/15-modernization/EVD-H-02-quickstart-after.txt vs evidence/07-repo-assessment/EVD-C-02-quickstart-transcript.txt; CI run 2 | G5: n/a
A6: F-03 | B6: S3 | C6: The documented run command is wrong | D6: FIXED | E6: R1 | F6: README Quick Start; EVD-H-02 | G6: n/a
A7: F-04 | B7: S2 | C7: No dependency lockfile for either stack | D7: FIXED | E7: R2 | F7: hash-pinned requirements.txt/requirements-dev.txt (--require-hashes in CI run 2); apps/web/package-lock.json (lockfileVersion 3) | G7: Web lead (UNRESOLVED) | H7: npm audit not run (DEBT-14)
A8: F-05 | B8: S2 | C8: Documentation claims a portal that does not exist | D8: CHANGED | E8: R1;R4 | F8: README corrected; thin static operations view; tests/test_ops_view.py; EVD-J-04-browser-e2e.json | G8: Product owner (UNRESOLVED) | H8: Angular portal NOT built; OQ-06 ruling
A9: F-06 | B9: S3 | C9: The frontend lint gate is "lint": "echo scaffold" — a no-op that reports success. | D9: PARTIAL | E9: R2 | F9: apps/web/package.json lint now runs scripts/lint-scaffold.mjs instead of echo | G9: Web lead (UNRESOLVED) | H9: a scaffold check, not a framework linter; no frontend build exists (DEBT-10)
A10: F-07 | B10: S2 | C10: No containerisation or environment definition: no Dockerfile, no compose file, no devconta | D10: PARTIAL | E10: R2 | F10: Dockerfile, docker-compose.yml, entrypoint; EVD-P-02 exercises | G10: Platform lead (UNRESOLVED) | H10: image never built in this workspace (DEBT-06)
A11: F-08 | B11: S2 | C11: No change-control surface: no CONTRIBUTING.md, no PR template, no CODEOWNERS, no branch-pr | D11: PARTIAL | E11: R3 | F11: CODEOWNERS, PR template, CONTRIBUTING.md, SECURITY.md; GitHub API 2026-10-08: main branch not protected (HTTP 404) | G11: Repository owner (UNRESOLVED) | H11: branch protection needs admin action
A12: F-09 | B12: S1 | C12: A database password is hardcoded in source | D12: FIXED-IN-TREE | E12: R3 | F12: EVD-H-03-secret-scan.json (0 findings); tests/test_secret_scan.py | G12: Repository owner (UNRESOLVED) | H12: value still in git history and in public repo: see F-09 history row DEBT-11, RA-07
A13: F-10 | B13: S1 | C13: .env.example ships a complete DSN with embedded credentials: postgresql://app_shared:Welco | D13: FIXED-IN-TREE | E13: R3 | F13: EVD-H-03; scripts/secret_scan.py | G13: Repository owner (UNRESOLVED) | H13: history residual (DEBT-11)
A14: F-11 | B14: S2 | C14: .env.example ships AI_GATEWAY_KEY=sk-workshop-hardcoded-example — a key-shaped literal in | D14: FIXED-IN-TREE | E14: R3 | F14: EVD-H-03 | G14: Repository owner (UNRESOLVED) | H14: history residual (DEBT-11)
A15: F-12 | B15: S1 | C15: .env.example ships OT_VENDOR_TOKEN=replace-me-but-currently-shared — the comment itself do | D15: FIXED-IN-TREE | E15: R3 | F15: EVD-H-03 | G15: Repository owner (UNRESOLVED) | H15: history residual (DEBT-11)
A16: F-13 | B16: S2 | C16: .env.example sets LOG_LEVEL=DEBUG as the default, meaning verbose logging of operational p | D16: FIXED | E16: R3 | F16: tests/test_config.py | G16: n/a
A17: F-14 | B17: S1 | C17: No secret detection anywhere: no scanner in CI, no pre-commit hooks, no rotation policy | D17: FIXED | E17: R3 | F17: scripts/secret_scan.py in CI run 2; tests/test_secret_scan.py | G17: n/a
A18: F-15 | B18: S2 | C18: The IaC emits a credential artifact | D18: FIXED | E18: R3 | F18: tests/test_config.py; infra/terraform/main.tf emits no credential | G18: n/a
A19: F-16 | B19: S2 | C19: No encryption posture exists: no TLS configuration, no at-rest statement, no key managemen | D19: DEFERRED | E19: R3 | F19: GAP-01; privacy-impact-assessment.md | G19: Platform lead (UNRESOLVED) | H19: TLS and at-rest encryption belong to an undecided platform
A20: F-17 | B20: S1 | C20: Authorisation is a client-supplied HTTP header | D20: FIXED | E20: R3 | F20: tests/test_identity_policy.py; EVD-H-04; EVD-L-03 RT-02/RT-11 baseline succeed, v2 fail | G20: n/a
A21: F-18 | B21: S1 | C21: The role check is a flat five-element allow-list with no resource, tenant, facility, purpo | D21: FIXED | E21: R3 | F21: policy engine + access-semantics.yaml; EVD-H-04 allow/deny matrix | G21: n/a | H21: scope narrowing by hub/fleet not enforceable (DEBT-05)
A22: F-19 | B22: S1 | C22: The allow-list contains a persona from another domain | D22: FIXED | E22: R1;R3 | F22: characterization AB-04; RT-03 | G22: n/a
A23: F-20 | B23: S1 | C23: The AI endpoint has no authorisation check whatsoever | D23: FIXED | E23: R3 | F23: characterization AB-06; RT-01 | G23: n/a
A24: F-21 | B24: S1 | C24: policy/opa/access.rego is role-only (admin → all, operator → read) | D24: FIXED | E24: R3 | F24: policy/opa/access.rego generated from access-semantics; opa check and opa test green in CI run 2 | G24: n/a | H24: engine in request path is Python; OPA parity test skipped locally, run in CI
A25: F-22 | B25: S1 | C25: Prompt injection surface | D25: FIXED | E25: R3 | F25: tests/test_ai_gateway.py; RT-07 baseline succeeds, v2 fails | G25: n/a | H25: tested with constructed payloads only (F-60)
A26: F-23 | B26: S2 | C26: Using str.format() on attacker-influenceable content is additionally a format-string injec | D26: FIXED | E26: R3 | F26: tests/test_ai_gateway.py (no str.format on data) | G26: n/a
A27: F-24 | B27: S1 | C27: The system self-reports that no guardrail exists: the response literal is "guardrail_statu | D27: FIXED | E27: R3 | F27: characterization AB-07; RT-09 | G27: n/a | H27: guardrail is deterministic; untested against a real model
A28: F-25 | B28: S1 | C28: No output schema validation | D28: FIXED | E28: R3 | F28: schema validation in gateway; EVD-H-07 | G28: n/a
A29: F-26 | B29: S1 | C29: No human approval gate | D29: FIXED | E29: R3 | F29: tests/test_human_control.py (9); RT-10 | G29: n/a | H29: self-approval still possible (HC-R-01, RA-04)
A30: F-27 | B30: S1 | C30: Model provenance is a module constant (MODEL_VERSION = "local-sim-v1") | D30: FIXED | E30: R3 | F30: prompts.lock.json, models.lock.json, registry; tests/test_prompt_lock.py | G30: n/a
A31: F-28 | B31: S2 | C31: Token accounting is fabricated: token_estimate = len(prompt.split()) * 2 | D31: PARTIAL | E31: R2;R3 | F31: tokens are estimates; EVD-H-07 | G31: AI lead (UNRESOLVED) | H31: real counts only with a real model
A32: F-29 | B32: S1 | C32: The AI output is not derived from the record's meaning | D32: PARTIAL | E32: R1;R4 | F32: deterministic summary from allow-listed facts (AB-08) | G32: AI lead (UNRESOLVED) | H32: ETA Prediction, Route Optimization, Exception Copilot remain NOT IMPLEMENTED; answer quality unproven
A33: F-30 | B33: S1 | C33: Cross-entity primary-key collision | D33: FIXED | E33: R1;R2 | F33: tests/test_record_lookup.py; RT-06 | G33: n/a | H33: REC-0001 rejected by key pattern; owner intent OQ-15 unresolved
A34: F-31 | B34: S1 | C34: Record lookup scans every column, not the key | D34: FIXED | E34: R2 | F34: tests/test_record_lookup.py; RT-04 | G34: n/a
A35: F-32 | B35: S1 | C35: A missed lookup silently returns the wrong record | D35: FIXED | E35: R1;R2 | F35: characterization + 404/422; RT-05 | G35: n/a
A36: F-33 | B36: S2 | C36: Three duplicate business keys in every dataset, at a consistent *-00004, *-00013, *-00019 | D36: FIXED | E36: R1 | F36: tests/test_etl_quarantine.py; EVD-H-06 | G36: n/a | H36: quarantined to data/quarantine; fixture untouched
A37: F-34 | B37: S2 | C37: One fully-blank mandatory row in every dataset — every non-key column empty (10 blank colu | D37: FIXED | E37: R1 | F37: tests/test_etl_quarantine.py | G37: n/a
A38: F-35 | B38: S2 | C38: One impossible timestamp per timestamped dataset: 1900-01-01T00:00:00 in shipments.promise | D38: FIXED | E38: R1 | F38: tests/test_etl_quarantine.py | G38: n/a
A39: F-36 | B39: S2 | C39: tracking_events.confidence spans 0.001–1.42 | D39: FIXED | E39: R1;R2 | F39: ETL validation rules; EVD-H-06 | G39: n/a
A40: F-37 | B40: S1 | C40: No semantic layer: categorical columns are polluted with workflow-status vocabulary | D40: FIXED | E40: R1;R2 | F40: semantic-layer/ (status-taxonomy, enum-violations.md); enforced in ETL | G40: n/a | H40: enum meaning of 14 tokens is inferred, not owner-confirmed
...

Sheet Red Team
A1: Red team: the same 12 attacks against Repo 1.0 and Repo 2.0
A2: Source: evidence/26-tevv/EVD-L-03-redteam-baseline.json and EVD-L-03-redteam-v2.json. Run by the builder, not an independent team.
A3: Attack | B3: Finding | C3: Goal | D3: Repo 1.0 HTTP | E3: Repo 1.0 result | F3: Repo 2.0 HTTP | G3: Repo 2.0 result
A4: RT-01 | B4: F-20 | C4: invoke the AI endpoint with no identity | D4: 200 | E4: Succeeded | F4: 401 | G4: Failed
A5: RT-02 | B5: F-17 | C5: self-assert an admin role with a header | D5: 200 | E5: Succeeded | F5: 401 | G5: Failed
A6: RT-03 | B6: F-19 | C6: use a persona from another domain | D6: 200 | E6: Succeeded | F6: 401 | G6: Failed
A7: RT-04 | B7: F-31 | C7: look up a record through a non-key column | D7: 200 | E7: Succeeded | F7: 422 | G7: Failed
A8: RT-05 | B8: F-32 | C8: ask for a record that does not exist | D8: 200 | E8: Succeeded | F8: 422 | G8: Failed
A9: RT-06 | B9: F-30 | C9: reach the planted colliding key | D9: 200 | E9: Succeeded | F9: 422 | G9: Failed
A10: RT-07 | B10: F-22 | C10: get attacker text reflected through the AI output | D10: 200 | E10: Succeeded | F10: 422 | G10: Failed
A11: RT-08 | B11: F-22 | C11: get attacker text from a categorical field into the AI output | D11: 200 | E11: Failed | F11: 200 | G11: Failed
A12: RT-09 | B12: F-24 | C12: find the guardrail switched off | D12: 200 | E12: Succeeded | F12: 200 | G12: Failed
A13: RT-10 | B13: F-26 | C13: action a suggestion without any human approval step | D13: 404 | E13: Failed | F13: 401 | G13: Failed
A14: RT-11 | B14: F-17 | C14: forge a token (alg none, role admin) | D14: 200 | E14: Succeeded | F14: 401 | G14: Failed
A15: RT-12 | B15: F-46/NFR | C15: exhaust the AI endpoint without a limit | D15: 200 | E15: Succeeded | F15: 429 | G15: Failed
C16: Attacks that succeeded | E16: =COUNTIF(E4:E15,"Succeeded") -> 10 | G16: =COUNTIF(G4:G15,"Succeeded") -> 0

Sheet KPIs
A1: KPIs K1 to K10: before and after
A2: Source: docs/34-after-kpis/after-intervention-kpi-sheet.md; evidence/34-after-kpis/EVD-O-01-after-kpis.json. K9 re-run on 2026-10-08. None of this is a business outcome.
A3: KPI | B3: Measure | C3: Baseline | D3: After | E3: Equal? | F3: Reading
A4: K1 | B4: Latency p50 / p95 / max (ms) | C4: 1667 / 13709 / 14999 | D4: 1667 / 13709 / 14999 | E4: yes | F4: A column of the static fixture, not a service measurement
A5: K2 | B5: Cost per event | C5: 2.2451 | D5: 2.2451 | E5: yes | F5: Static fixture
A6: K3 | B6: Severe-event share | C6: 39.6% | D6: 39.6% | E6: yes | F6: Static fixture
A7: K4 | B7: Correlation completeness (source stream) | C7: 33.6% | D7: 33.6% | E7: yes | F7: The producer still emits no id (F-42)
A8: K5 | B8: Declared AI tokens | C8: 904,432 | D8: 904,432 | E8: yes | F8: Declared by the dataset
A9: K6 | B9: Retries min / mean / max | C9: 51 / 2508.5 / 4995 | D9: 51 / 2508.5 / 4995 | E9: yes | F9: Static fixture
A10: K7 | B10: Duplicate keys (raw layer) | C10: 18 | D10: 18 | E10: yes | F10: Seeded defects stay in the raw files; quarantined downstream
A11: K8 | B11: Incomplete rows (raw layer) | C11: 6 | D11: 6 | E11: yes | F11: Seeded defects stay in the raw files; quarantined downstream
A12: K9 | B12: Tests | C12: 3 of 3 pass (0 collected without httpx) | D12: 181 passed, 7 expected xfail (170 at Stage O) | E12: n/a | F12: Engineering health, not operations
A13: K10 | B13: Coverage | C13: 45% | D13: 97% (apps and etl) | E13: n/a | F13: Engineering health

Sheet Rubric Coverage
A1: Rubric coverage: sub-dimensions per criterion
A2: Source: docs/43-rubric-traceability/readiness-assessment.md (counts) and EVD-S-01-coverage-matrix.csv (rows below). Index = (MET + 0.5 x PARTIAL) / sub-dimensions. It measures evidence completeness, not marks.
A3: Criterion | B3: Name | C3: Marks | D3: MET | E3: PARTIAL | F3: NOT MET | G3: BLOCKED | H3: Sub-dimensions | I3: Coverage index
A4: R1 | B4: As-Is understanding | C4: 20 | D4: 6 | E4: 1 | F4: 0 | G4: 0 | H4: =SUM(D4:G4) -> 7 | I4: =IF(H4=0,0,(D4+0.5*E4)/H4) -> 0.92857143
A5: R2 | B5: Repo 2.0 design | C5: 25 | D5: 5 | E5: 4 | F5: 0 | G5: 0 | H5: =SUM(D5:G5) -> 9 | I5: =IF(H5=0,0,(D5+0.5*E5)/H5) -> 0.77777778
A6: R3 | B6: Governance, risk, security | C6: 20 | D6: 5 | E6: 2 | F6: 1 | G6: 1 | H6: =SUM(D6:G6) -> 9 | I6: =IF(H6=0,0,(D6+0.5*E6)/H6) -> 0.66666667
A7: R4 | B7: PRD and working application | C7: 25 | D7: 4 | E7: 1 | F7: 0 | G7: 1 | H7: =SUM(D7:G7) -> 6 | I7: =IF(H7=0,0,(D7+0.5*E7)/H7) -> 0.75
A8: R5 | B8: Presentation and defence | C8: 10 | D8: 4 | E8: 1 | F8: 0 | G8: 0 | H8: =SUM(D8:G8) -> 5 | I8: =IF(H8=0,0,(D8+0.5*E8)/H8) -> 0.9
A9: Total | C9: =SUM(C4:C8) -> 100 | D9: =SUM(D4:D8) -> 24 | E9: =SUM(E4:E8) -> 9 | F9: =SUM(F4:F8) -> 1 | G9: =SUM(G4:G8) -> 2 | H9: =SUM(H4:H8) -> 36
A11: File-level matrix rows (each row: a sub-dimension, its status, and one file that evidences it)
A12: Criterion | B12: Sub-dimension | C12: Status | D12: Evidence file | E12: SHA-256
A13: R1 | B13: Understanding Repo 1.0 | C13: MET | D13: docs/00-preflight/discovery/system-landscape.md | E13: c9e01c93ab63e0158e6c2d8055095cf5fadaef9cb9755f927fc02617627bead3
A14: R1 | B14: Understanding Repo 1.0 | C14: MET | D14: docs/00-preflight/discovery/security-observability-overview.md | E14: 2a4de67330bd63114e7baf006e29a48538dc895574ae34dae41fd034de1bbb98
A15: R1 | B15: Understanding Repo 1.0 | C15: MET | D15: docs/00-preflight/discovery/assumptions-unknowns.md | E15: c6d6d21ccb0e9f84805b8b48466e1c3f91ca5144f69f1afde3515ce52e1deb13
A16: R1 | B16: Understanding Repo 1.0 | C16: MET | D16: docs/00-preflight/discovery/test-overview.md | E16: 8f6427f52af572ae1148000707e5a3037a0f997007f15aaf3aaaa0b21de012fe
A17: R1 | B17: Understanding Repo 1.0 | C17: MET | D17: docs/00-preflight/discovery/environment-snapshot.md | E17: 3183093fa1a009c5479a572c026ac4d732cb0234b226424c4e2aff9587aa9c44
A18: R1 | B18: Understanding Repo 1.0 | C18: MET | D18: docs/05-current-state/manual-handoffs.md | E18: 3bff471d8b925e062cebdd95b1a1d539fc50488674b25a3b66f4caccd305782e
A19: R1 | B19: Understanding Repo 1.0 | C19: MET | D19: docs/05-current-state/brownfield-inventory.md | E19: be7a4e9b6064139d8ae3b2ac8722846843abc5208983556123515f0ab0115815
A20: R1 | B20: Understanding Repo 1.0 | C20: MET | D20: docs/05-current-state/system-landscape.md | E20: ebaaf6e1ffc7aae411cfd2410f0cf2c9396ff767e342d38b3be843fdbce4d62a
A21: R1 | B21: Understanding Repo 1.0 | C21: MET | D21: docs/05-current-state/current-state-summary.md | E21: af98be49a093cacc8c85a9d6e50631553d06fc225fe3e2d8e613fa266ef7ab8b
A22: R1 | B22: Understanding Repo 1.0 | C22: MET | D22: docs/05-current-state/dependency-hotspots.md | E22: 0676ad01ad5346459505e66bb23967bbf5e4e69fcf3b77b08098796049a3cde2
A23: R1 | B23: Understanding Repo 1.0 | C23: MET | D23: docs/07-repo-assessment/repo-assessment.md | E23: 0b1f2f8ad6ab41854913dba2a45588ef81cc428eb48946c30cd24a5fbec08b9d
... A131: R5 | B131: Answering evaluator questions | C131: MET | D131: evidence/EVIDENCE-INDEX.md | E131: cd744fa5b570efad24d3b8a2b4165ae695516d4d9d1349631a544d9aba27d551

Sheet Go-No-Go
A1: Readiness gates G1 to G12
A2: Source: docs/30-release/go-no-go-criteria.md (fixed before the decision) and docs/42-executive/production-readiness-decision.md; G1 and G9 updated to today. Pilot needs G1-G7; production needs G8-G12 as well.
A3: Gate | B3: Criterion | C3: Mandatory for | D3: State | E3: Basis
A4: G1 | B4: Tests pass, coverage at or above floor | C4: yes | D4: PASS | E4: 181 passed, 97% (apps and etl); CI green on 3.11 and 3.14
A5: G2 | B5: Evaluation at thresholds | C5: yes | D5: PASS (deterministic provider only) | E5: 192 cases, 0 failures; real model untested
A6: G3 | B6: No original defect re-exploitable | C6: yes | D6: PASS | E6: 0 of 12 attacks succeed
A7: G4 | B7: No known critical or high dependency vulnerability | C7: yes | D7: PASS | E7: pip-audit: 0
A8: G5 | B8: Audit tamper-evident; reconstruction shown | C8: yes | D8: PASS (author-run) | E8: EVD-N-02
A9: G6 | B9: Backup restore shown | C9: yes | D9: PASS (repository level) | E9: EVD-N-03
A10: G7 | B10: Rollback defined and rehearsed | C10: yes | D10: PARTIAL | E10: Defined; no cutover exists
A11: G8 | B11: Alerts routed to named humans | C11: yes | D11: FAIL | E11: No collector, no recipients
A12: G9 | B12: Named approver and risk owners | C12: yes | D12: FAIL | E12: Operator approves under provisional authority (OQ-05); 0 of 12 risk acceptances signed
A13: G10 | B13: Platform and identity provider exist | C13: production | D13: FAIL | E13: Platform-neutral by decision (OQ-01); IdP deferred (OQ-07)
A14: G11 | B14: Independent evidence review | C14: yes | D14: FAIL | E14: Builder and grader are the same agent
A15: G12 | B15: Compliance resolved | C15: real data | D15: FAIL | E15: No regime named (OQ-04); candidate obligations unvalidated

Sheet Decisions
A1: 23 open questions: the operator's decisions (Runbook 04)
A2: Source: docs/44-decisions/open-questions-register-v2.md; record evidence/44-decisions/EVD-T-01-operator-decision-record.json. One person holds every role, so these are provisional.
A3: Question | B3: Subject | C3: Status | D3: Decision | E3: What it means now
A4: OQ-01 | B4: Target platform | C4: DECIDED | D4: Stay platform-neutral. No cloud or runtime is named. | E4: ADR-0009 stands: container image and compose file; IaC stays a non-provisioning stub (M-X2 stays NOT MET, accepted).
A5: OQ-02 | B5: Model A and Model B | C5: DECIDED | D5: No model is used. The deterministic provider stays the only provider. | E5: R4 'Working AI capabilities' stays BLOCKED, now accepted by the operator. The Stage Q builder comparison (Sonnet vs Haiku, same vendor) stays the only portability evidence.
A6: OQ-03 | B6: Network egress | C6: DECIDED | D6: No network egress from the application. Build and demo run offline. | E6: Matches what was built (offline demo, no model call).
A7: OQ-04 | B7: Regulatory obligations | C7: DECIDED | D7: No regime is named. The candidate obligations set stays an unvalidated working assumption. | E7: `docs/25-governance/compliance-obligations.md` stays labelled candidate; RA-01 remains an unsigned risk acceptance.
A8: OQ-05 | B8: Stakeholders and approvers | C8: DECIDED | D8: The operator (Dinesh) approves everything as Transformation Lead, under provisional authority. No other named party exists. A CTO review stays recommended. | E8: Gates stay self-signed and PROVISIONAL. This records the arrangement; it does not make the approvals independent. G9 and GOV-10 stay open.
A9: OQ-06 | B9: Operator portal in scope | C9: RATIFIED | D9: A thin read-only operations view, not an Angular portal. Previously RESOLVED (provisional). | E9: B-7 resolved by decision.
A10: OQ-07 | B10: Identity provider | C10: DEFERRED | D10: No provider chosen. HS256 stays an interim scheme, not for production; JWKS stays a fail-closed stub. | E10: Production identity remains an explicit gap (ADR-0004).
A11: OQ-08 | B11: Proxy KPIs acceptable | C11: RATIFIED | D11: The labelled proxy KPIs are accepted as the frozen baseline. No real business data exists. | E11: Stage O comparison is valid only as proxies; the comparability caveat stays in the narrative.
A12: OQ-09 | B12: Financial data for ROI | C12: DECIDED | D12: No financial data. The benefit model stays in analyst-hours with sensitivity ranges and no money figure. | E12: NPV -970 h expected, +5,525 h optimistic, -2,466 h downside stays the statement; verified benefit is nil.
A13: OQ-10 | B13: Evidence retention | C13: RATIFIED | D13: Evidence stays in the repository, hash-manifested and version-controlled. | E13: Retention classes stay as written; there is no external append-only audit sink for runtime records.
A14: OQ-11 | B14: Authorisation to write | C14: RATIFIED | D14: The operator ratifies, in their own name, the write authorisation given as instruction D-009. A CTO ratification stays recommended. | E14: EVD-G-04 stays unsigned as a document; this decision is recorded in EVD-T-01 and D-016.
... A26: OQ-23 | B26: Team size and skills | C26: DECIDED | D26: One operator plus the agent; sequential execution. | E26: Stage ordering stays sequential; no parallel plan is needed.

Sheet Risks
A1: Residual risks (none accepted by a named person)
A2: Source: docs/42-executive/residual-risks.md and docs/25-governance/risk-acceptance-register.md, with the Runbook 04 decisions applied. Owners are roles.
A3: ID | B3: Risk | C3: Severity (agent view) | D3: Owner role | E3: Current position
A4: RA-07 / DEBT-11 | B4: Credential-shaped values remain in git history | C4: High | D4: Repository owner + Security | E4: Repository private; values treated as compromised; history not rewritten (OQ-19)
A5: RA-01 | B5: Regulatory scope unresolved | C5: High for real data | D5: Sponsor + Compliance | E5: No regime named (OQ-04); pilot on synthetic data only
A6: RA-06 / TEVV-R-01 | B6: Builder and grader are the same agent; no independent review | C6: High | D6: Release approver | E6: Blocks an unconditional GO; ask 6 to the CTO
A7: RA-02 | B7: HS256 shared-secret identity; JWKS stub | C7: High if networked | D7: Security | E7: Interim scheme kept (OQ-07 deferred)
A8: RA-09 / TEVV-R-02 | B8: Real model untested; thresholds valid only for the deterministic provider | C8: High before a model | D8: AI governance | E8: No model by decision (OQ-02)
A9: Stage Q | B9: Model portability partly shown: safety yes, AI-output fidelity no | C9: Medium | D9: AI governance | E9: 8 gaps specified in semantic layer v2.0; not re-tested
A10: RA-04 / HC-R-01 | B10: No four-eyes: requester can approve their own suggestion | C10: Medium | D10: Product | E10: Before any action integration
A11: RA-12 / DEBT-01 | B11: Branch protection not enabled on main | C11: Medium | D11: Repository owner | E11: GitHub reports the feature needs Pro for a private repository
A12: DEBT-06 / F-48 | B12: Terraform provisions nothing; image never built | C12: Medium | D12: Platform | E12: Platform-neutral by decision (OQ-01)
A13: N-R | B13: No tracing; collector and alerts never run; no recipients | C13: Medium | D13: SRE | E13: Before deployment
A14: DEBT-04 | B14: Audit sink is a local file; deletion of the tip cannot be prevented | C14: Medium | D14: Platform | E14: Needs a platform
... A17: Value | B17: No business KPI measurable; NPV negative at fixture volume | C17: Medium | D17: Sponsor | E17: Measure review time first
A18: RA-03, 05, 08, 10, 11 | B18: Purpose defaulting; approvals never expire; stale GPS undetectable; retention undefined; in-memory rate limit | C18: Low to Medium | D18: See risk-acceptance register

Sheet Journey
A1: Delivery journey: 20 stages in six phases
A2: Stages A to R come from runbook/02-TRANSFORMATION-RUNBOOK.md; S and T are Runbooks 03 and 04. Evidence count = rows in the Evidence Register for that stage letter.
A3: Stage | B3: Phase | C3: Stage name | D3: Commit(s) | E3: Evidence files
A4: A | B4: 1 Understand | C4: Engagement mobilisation and read-only orientation | D4: 698e858, f1b7809 | E4: 15
A5: B | B5: 1 Understand | C5: Qualification, stakeholders and problem framing | D5: f1b7809 | E5: 1
A6: C | B6: 1 Understand | C6: Baseline: KPIs, current state, root cause, behaviour | D6: 4c84af1 | E6: 10
A7: D | B7: 2 Define | C7: Semantic layer extraction | D7: 4c84af1 | E7: 9
A8: E | B8: 2 Define | C8: Intervention qualification and initial PRD | D8: 4c84af1 | E8: 2
A9: F | B9: 2 Define | C9: Target architecture, data and context, specs, traceability | D9: 4c84af1 | E9: 8
A10: G | B10: 2 Define | C10: Transformation and migration planning | D10: 4c84af1 | E10: 3
A11: H | B11: 3 Build | C11: Repo 2.0 modernisation and validation | D11: 4c84af1 | E11: 17
A12: I | B12: 3 Build | C12: Implementation PRD and delivery planning | D12: 4c84af1 | E12: 0
A13: J | B13: 3 Build | C13: Intelligence core, application, integration and agents | D13: 4c84af1 | E13: 9
A14: K | B14: 4 Prove | C14: Human control, security, privacy, responsible AI, governance | D14: 4c84af1 | E14: 3
A15: L | B15: 4 Prove | C15: TEVV and AI red teaming | D15: 4c84af1 | E15: 3
... A23: T | B23: 6 Close-out | C23: Open questions and decisions (Runbook 04) | D23: 1cde803 | E23: 1
A24: D (v2) | B24: 6 Close-out | C24: Semantic layer aligned to semantic-layer-build.txt | D24: ad230eb | E24: (in D)

Sheet Semantic Layer
A1: Semantic layer v2.0: files
A2: The model-independent definition of the domain. Hashes recorded in evidence/11-data-context/EVD-D-06-semantic-layer-v2-hashes.json.
A3: File | B3: Format and role | C3: Bytes | D3: Link
A4: semantic-layer/README.md | B4: Markdown: for people | C4: 3526 | D4: open
A5: semantic-layer/SEMANTIC-COMPLETENESS.md | B5: Markdown: for people | C5: 5219 | D5: open
A6: semantic-layer/access-semantics.yaml | B6: YAML: definition | C6: 7756 | D6: open
A7: semantic-layer/ai-context-policy.yaml | B7: YAML: definition | C7: 1568 | D7: open
A8: semantic-layer/api-contract.json | B8: JSON / JSON Schema | C8: 3494 | D8: open
A9: semantic-layer/business-rules.yaml | B9: YAML: definition | C9: 5598 | D9: open
A10: semantic-layer/domain-knowledge.md | B10: Markdown: for people | C10: 3795 | D10: open
A11: semantic-layer/entities.yaml | B11: YAML: definition | C11: 23145 | D11: open
A12: semantic-layer/enum-violations.md | B12: Markdown: for people | C12: 6272 | D12: open
A13: semantic-layer/generate.py | B13: Generator or test | C13: 1071 | D13: open
A14: semantic-layer/generated/semantic-layer.json | B14: JSON / JSON Schema | C14: 66333 | D14: open
A15: semantic-layer/glossary.md | B15: Markdown: for people | C15: 7284 | D15: open
... A23: semantic-layer/workflow-semantics.yaml | B23: YAML: definition | C23: 6597 | D23: open
